WARNING: Retrying (Retry(total=4, connect=None, read=None, redirect=None, status=None)) after connection broken by 'NewConnectionError('<pip._vendor.urllib3.connection.VerifiedHTTPSConnection object at 0x2b23913a9070>: Failed to establish a new connection: [Errno 101] Network is unreachable')': /simple/pip/
WARNING: Retrying (Retry(total=3, connect=None, read=None, redirect=None, status=None)) after connection broken by 'NewConnectionError('<pip._vendor.urllib3.connection.VerifiedHTTPSConnection object at 0x2b23913a9250>: Failed to establish a new connection: [Errno 101] Network is unreachable')': /simple/pip/
WARNING: Retrying (Retry(total=2, connect=None, read=None, redirect=None, status=None)) after connection broken by 'NewConnectionError('<pip._vendor.urllib3.connection.VerifiedHTTPSConnection object at 0x2b23913a9400>: Failed to establish a new connection: [Errno 101] Network is unreachable')': /simple/pip/
WARNING: Retrying (Retry(total=1, connect=None, read=None, redirect=None, status=None)) after connection broken by 'NewConnectionError('<pip._vendor.urllib3.connection.VerifiedHTTPSConnection object at 0x2b23913a9580>: Failed to establish a new connection: [Errno 101] Network is unreachable')': /simple/pip/
WARNING: Retrying (Retry(total=0, connect=None, read=None, redirect=None, status=None)) after connection broken by 'NewConnectionError('<pip._vendor.urllib3.connection.VerifiedHTTPSConnection object at 0x2b23913a9700>: Failed to establish a new connection: [Errno 101] Network is unreachable')': /simple/pip/
WARNING: Retrying (Retry(total=4, connect=None, read=None, redirect=None, status=None)) after connection broken by 'NewConnectionError('<pip._vendor.urllib3.connection.VerifiedHTTPSConnection object at 0x2b2391b30b20>: Failed to establish a new connection: [Errno 101] Network is unreachable')': /simple/pip/
WARNING: Retrying (Retry(total=3, connect=None, read=None, redirect=None, status=None)) after connection broken by 'NewConnectionError('<pip._vendor.urllib3.connection.VerifiedHTTPSConnection object at 0x2b2391b30cd0>: Failed to establish a new connection: [Errno 101] Network is unreachable')': /simple/pip/
WARNING: Retrying (Retry(total=2, connect=None, read=None, redirect=None, status=None)) after connection broken by 'NewConnectionError('<pip._vendor.urllib3.connection.VerifiedHTTPSConnection object at 0x2b2391b30e20>: Failed to establish a new connection: [Errno 101] Network is unreachable')': /simple/pip/
WARNING: Retrying (Retry(total=1, connect=None, read=None, redirect=None, status=None)) after connection broken by 'NewConnectionError('<pip._vendor.urllib3.connection.VerifiedHTTPSConnection object at 0x2b2391b30f70>: Failed to establish a new connection: [Errno 101] Network is unreachable')': /simple/pip/
WARNING: Retrying (Retry(total=0, connect=None, read=None, redirect=None, status=None)) after connection broken by 'NewConnectionError('<pip._vendor.urllib3.connection.VerifiedHTTPSConnection object at 0x2b2391b39100>: Failed to establish a new connection: [Errno 101] Network is unreachable')': /simple/pip/
ERROR: Could not find a version that satisfies the requirement install (from versions: none)
ERROR: No matching distribution found for install
Traceback (most recent call last):
  File "/home/daril/trajcbert/first_test_small_train_gpu.py", line 2, in <module>
    from sklearn.metrics import f1_score
  File "/home/daril/.local/lib/python3.9/site-packages/sklearn/__init__.py", line 79, in <module>
    from . import (
ImportError: cannot import name '__check_build' from partially initialized module 'sklearn' (most likely due to a circular import) (/home/daril/.local/lib/python3.9/site-packages/sklearn/__init__.py)
